<?xml version='1.0'?>
<robot name="mogi_bot" xmlns:xacro="http://www.ros.org/wiki/xacro">

  <!-- STEP 1 - Robot footprint -->
  <link name="base_footprint"></link>

    <!-- STEP 2 - Robot chassis = base_link -->
    <joint name="base_footprint_joint" type="fixed">
      <origin xyz="0 0 0" rpy="0 0 0" />
      <parent link="base_footprint"/>
      <child link="base_link" />
    </joint>

    <link name='base_link'>
      <pose>0 0 0.1 0 0 0</pose>

      <inertial>
        <mass value="15.0"/>
        <origin xyz="0.0 0 0" rpy=" 0 0 0"/>
        <inertia
            ixx="0.0625" ixy="0" ixz="0"
            iyy="0.2125" iyz="0"
            izz="0.25"
        />
      </inertial>

      <collision name='collision'>
        <origin xyz="0 0 0" rpy=" 0 0 0"/>
        <geometry>
          <box size=".4 .2 .1"/>
        </geometry>
      </collision>

          <collision name='rear_caster_collision'>
            <origin xyz="-0.15 0 -0.05" rpy=" 0 0 0"/>
            <geometry>
              <sphere radius="0.0499"/>
            </geometry>
          </collision>

          <visual name='rear_caster_visual'>
            <origin xyz="-0.15 0 -0.05" rpy=" 0 0 0"/>
            <geometry>
              <sphere radius="0.05"/>
            </geometry>
          </visual>

          <collision name='front_caster_collision'>
            <origin xyz="0.15 0 -0.05" rpy=" 0 0 0"/>
            <geometry>
              <sphere radius="0.0499"/>
            </geometry>
          </collision>

          <visual name='front_caster_visual'>
            <origin xyz="0.15 0 -0.05" rpy=" 0 0 0"/>
            <geometry>
              <sphere radius="0.05"/>
            </geometry>
          </visual>

      <visual name='base_link_visual'>
        <origin xyz="0 0 0" rpy=" 0 0 0"/>
        <geometry>
          <box size=".4 .2 .1"/>
        </geometry>
      </visual>
    </link>

      <!-- STEP 3 - Wheels -->
      <joint type="continuous" name="left_wheel_joint">
        <origin xyz="0 0.15 0" rpy="0 0 0"/>
        <child link="left_wheel"/>
        <parent link="base_link"/>
        <axis xyz="0 1 0" rpy="0 0 0"/>
        <limit effort="100" velocity="10"/>
        <dynamics damping="1.0" friction="1.0"/>
      </joint>

      <link name='left_wheel'>
        <inertial>
          <mass value="5.0"/>
          <origin xyz="0 0 0" rpy="0 1.5707 1.5707"/>
          <inertia
              ixx="0.014" ixy="0" ixz="0"
              iyy="0.014" iyz="0"
              izz="0.025"
          />
        </inertial>

        <collision>
          <origin xyz="0 0 0" rpy="0 1.5707 1.5707"/>
          <geometry>
            <cylinder radius=".1" length=".05"/>
          </geometry>
        </collision>

        <visual name='left_wheel_visual'>
          <origin xyz="0 0 0" rpy="0 1.5707 1.5707"/>
          <geometry>
            <cylinder radius=".1" length=".05"/>
          </geometry>
        </visual>
      </link>

      <joint type="continuous" name="right_wheel_joint">
        <origin xyz="0 -0.15 0" rpy="0 0 0"/>
        <child link="right_wheel"/>
        <parent link="base_link"/>
        <axis xyz="0 1 0" rpy="0 0 0"/>
        <limit effort="100" velocity="10"/>
        <dynamics damping="1.0" friction="1.0"/>
      </joint>

      <link name='right_wheel'>
        <inertial>
          <mass value="5.0"/>
          <origin xyz="0 0 0" rpy="0 1.5707 1.5707"/>
          <inertia
              ixx="0.014" ixy="0" ixz="0"
              iyy="0.014" iyz="0"
              izz="0.025"
          />
        </inertial>

        <collision>
          <origin xyz="0 0 0" rpy="0 1.5707 1.5707"/>
          <geometry>
            <cylinder radius=".1" length=".05"/>
          </geometry>
        </collision>

        <visual name='right_wheel_visual'>
          <origin xyz="0 0 0" rpy="0 1.5707 1.5707"/>
          <geometry>
            <cylinder radius=".1" length=".05"/>
          </geometry>
        </visual>
      </link>

    <gazebo>
        <plugin name="gazebo_ros2_control" filename="libgazebo_ros2_control.so">
            <parameters>$(find two_wheeled_cart)/config/controller.yaml</parameters>
        </plugin>
    </gazebo>

    <ros2_control name="mogi_bot_control" type="system">
        <hardware>
            <plugin>gazebo_ros2_control/GazeboSystem</plugin>
        </hardware>
        <joint name="left_wheel_joint">
            <command_interface name="velocity"/>
            <state_interface name="position"/>
            <state_interface name="velocity"/>
        </joint>
        <joint name="right_wheel_joint">
            <command_interface name="velocity"/>
            <state_interface name="position"/>
            <state_interface name="velocity"/>
        </joint>
    </ros2_control>



</robot>