<?xml version="1.0"?>
<robot name="simple_two_wheel_cart">

  <!-- ========== 材料定义 ========== -->
  <material name="blue">
    <color rgba="0.0 0.0 0.8 1.0"/>
  </material>
  <material name="black">
    <color rgba="0.0 0.0 0.0 1.0"/>
  </material>
  <material name="gray">
    <color rgba="0.7 0.7 0.7 1.0"/>
  </material>

  <!-- ========== 基础链接 - 小车底盘 ========== -->
  <link name="base_link">
    <visual>
      <geometry>
        <box size="0.4 0.2 0.1"/>
      </geometry>
      <material name="blue"/>
    </visual>
    <collision>
      <geometry>
        <box size="0.4 0.2 0.1"/>
      </geometry>
    </collision>
    <inertial>
      <mass value="2.0"/>
      <inertia ixx="0.01" ixy="0.0" ixz="0.0" iyy="0.01" iyz="0.0" izz="0.01"/>
    </inertial>
  </link>

  <!-- ========== 左轮 ========== -->
  <link name="left_wheel">
    <visual>
      <origin xyz="0 0 0" rpy="1.5708 0 0"/>
      <geometry>
        <cylinder radius="0.05" length="0.03"/>
      </geometry>
      <material name="black"/>
    </visual>
    <collision>
      <origin xyz="0 0 0" rpy="1.5708 0 0"/>
      <geometry>
        <cylinder radius="0.05" length="0.03"/>
      </geometry>
    </collision>
    <inertial>
      <mass value="0.5"/>
      <inertia ixx="0.001" ixy="0.0" ixz="0.0" iyy="0.001" iyz="0.0" izz="0.001"/>
    </inertial>
  </link>

  <joint name="left_wheel_joint" type="continuous">
    <parent link="base_link"/>
    <child link="left_wheel"/>
    <origin xyz="0.0 0.1 -0.05" rpy="0 0 0"/>
    <axis xyz="0 1 0"/>
  </joint>

  <!-- ========== 右轮 ========== -->
  <link name="right_wheel">
    <visual>
      <origin xyz="0 0 0" rpy="1.5708 0 0"/>
      <geometry>
        <cylinder radius="0.05" length="0.03"/>
      </geometry>
      <material name="black"/>
    </visual>
    <collision>
      <origin xyz="0 0 0" rpy="1.5708 0 0"/>
      <geometry>
        <cylinder radius="0.05" length="0.03"/>
      </geometry>
    </collision>
    <inertial>
      <mass value="0.5"/>
      <inertia ixx="0.001" ixy="0.0" ixz="0.0" iyy="0.001" iyz="0.0" izz="0.001"/>
    </inertial>
  </link>

  <joint name="right_wheel_joint" type="continuous">
    <parent link="base_link"/>
    <child link="right_wheel"/>
    <origin xyz="0.0 -0.1 -0.05" rpy="0 0 0"/>
    <axis xyz="0 1 0"/>
  </joint>

  <!-- ========== 万向轮（支撑轮） ========== -->
  <link name="caster_wheel">
    <visual>
      <geometry>
        <sphere radius="0.02"/>
      </geometry>
      <material name="gray"/>
    </visual>
    <collision>
      <geometry>
        <sphere radius="0.02"/>
      </geometry>
    </collision>
    <inertial>
      <mass value="0.1"/>
      <inertia ixx="0.0001" ixy="0.0" ixz="0.0" iyy="0.0001" iyz="0.0" izz="0.0001"/>
    </inertial>
  </link>

  <joint name="caster_joint" type="fixed">
    <parent link="base_link"/>
    <child link="caster_wheel"/>
    <origin xyz="0.15 0.0 -0.07" rpy="0 0 0"/>
  </joint>

</robot>