<?xml version="1.0"?>
<robot name="two_wheeled_robot">

  <link name="base_link">
    <inertial>
      <mass value="5.0"/>
      <inertia ixx="0.1" ixy="0.0" ixz="0.0" iyy="0.1" iyz="0.0" izz="0.1"/>
    </inertial>
    <visual>
      <geometry>
        <box size="0.4 0.3 0.15"/>
      </geometry>
      <material name="blue">
        <color rgba="0.2 0.2 0.8 1"/>
      </material>
    </visual>
    <collision>
      <geometry>
        <box size="0.4 0.3 0.15"/>
      </geometry>
    </collision>
  </link>

  <link name="left_wheel">
    <inertial>
      <mass value="0.5"/>
      <inertia ixx="0.01" ixy="0.0" ixz="0.0" iyy="0.01" iyz="0.0" izz="0.01"/>
    </inertial>
    <visual>
      <geometry>
        <cylinder radius="0.08" length="0.05"/>
      </geometry>
      <material name="black">
        <color rgba="0 0 0 1"/>
      </material>
      <origin rpy="1.5708 0 0" xyz="0 0 0"/>
    </visual>
    <collision>
      <geometry>
        <cylinder radius="0.08" length="0.05"/>
      </geometry>
      <origin rpy="1.5708 0 0" xyz="0 0 0"/>
    </collision>
  </link>

  <link name="right_wheel">
    <inertial>
      <mass value="0.5"/>
      <inertia ixx="0.01" ixy="0.0" ixz="0.0" iyy="0.01" iyz="0.0" izz="0.01"/>
    </inertial>
    <visual>
      <geometry>
        <cylinder radius="0.08" length="0.05"/>
      </geometry>
      <material name="black">
        <color rgba="0 0 0 1"/>
      </material>
      <origin rpy="1.5708 0 0" xyz="0 0 0"/>
    </visual>
    <collision>
      <geometry>
        <cylinder radius="0.08" length="0.05"/>
      </geometry>
      <origin rpy="1.5708 0 0" xyz="0 0 0"/>
    </collision>
  </link>

  <!-- Joints -->
  <joint name="left_joint" type="continuous">
    <parent link="base_link"/>
    <child link="left_wheel"/>
    <origin xyz="0 -0.18 -0.075" rpy="0 0 0"/>
    <axis xyz="0 0 1"/>
  </joint>

  <joint name="right_joint" type="continuous">
    <parent link="base_link"/>
    <child link="right_wheel"/>
    <origin xyz="0 0.18 -0.075" rpy="0 0 0"/>
    <axis xyz="0 0 1"/>
  </joint>


  <ros2_control name="two_wheeled_robot_control" type="system">
    <hardware>
      <plugin>gz_ros2_control::GazeboSystem</plugin>
      <param name="joints">left_joint right_joint</param>
      <param name="use_sim_time">true</param>
    </hardware>
    <joint name="left_joint">
      <command_interface name="velocity"/>
      <state_interface name="position"/>
      <state_interface name="velocity"/>
    </joint>
    <joint name="right_joint">
      <command_interface name="velocity"/>
      <state_interface name="position"/>
      <state_interface name="velocity"/>
    </joint>
  </ros2_control>

</robot>